{"uuid": "00d3a72b-4900-48c8-b58f-89b8ccd51f7b", "children": ["e5c6dd93-3776-472c-8347-1dddafa99b06"], "befores": [{"name": "screenshot_on_failure", "status": "passed", "start": 1559919276328, "stop": 1559919276328}], "afters": [{"name": "screenshot_on_failure::fin", "status": "failed", "statusDetails": {"message": "Failed: Fixture \"app\" called directly. Fixtures are not meant to be called directly,\nbut are created automatically when test functions request them as parameters.\nSee https://docs.pytest.org/en/latest/fixture.html for more information about fixtures, and\nhttps://docs.pytest.org/en/latest/deprecations.html#calling-fixtures-directly about how to update your code.\n", "trace": "  File \"/Library/Frameworks/Python.framework/Versions/3.6/lib/python3.6/site-packages/allure_commons/_allure.py\", line 169, in __call__\n    return self._fixture_function(*args, **kwargs)\n  File \"/Users/ace/Documents/GitHub/epam_ta/pom/conftest.py\", line 37, in fin\n    driver = app()\n  File \"/Library/Frameworks/Python.framework/Versions/3.6/lib/python3.6/site-packages/_pytest/fixtures.py\", line 963, in result\n    fail(message, pytrace=False)\n  File \"/Library/Frameworks/Python.framework/Versions/3.6/lib/python3.6/site-packages/_pytest/outcomes.py\", line 116, in fail\n    raise Failed(msg=msg, pytrace=pytrace)\n"}, "start": 1559919282184, "stop": 1559919282184}], "start": 1559919276328, "stop": 1559919282184}