{"uuid": "b05596ad-906d-4b1e-8d32-1c53fbc3673a", "children": ["31b4631b-1cc6-4875-90d3-68cf119c93e3"], "befores": [{"name": "screenshot_on_failure", "status": "passed", "start": 1559919276295, "stop": 1559919276295}], "afters": [{"name": "screenshot_on_failure::fin", "status": "failed", "statusDetails": {"message": "Failed: Fixture \"app\" called directly. Fixtures are not meant to be called directly,\nbut are created automatically when test functions request them as parameters.\nSee https://docs.pytest.org/en/latest/fixture.html for more information about fixtures, and\nhttps://docs.pytest.org/en/latest/deprecations.html#calling-fixtures-directly about how to update your code.\n", "trace": "  File \"/Library/Frameworks/Python.framework/Versions/3.6/lib/python3.6/site-packages/allure_commons/_allure.py\", line 169, in __call__\n    return self._fixture_function(*args, **kwargs)\n  File \"/Users/ace/Documents/GitHub/epam_ta/pom/conftest.py\", line 37, in fin\n    driver = app()\n  File \"/Library/Frameworks/Python.framework/Versions/3.6/lib/python3.6/site-packages/_pytest/fixtures.py\", line 963, in result\n    fail(message, pytrace=False)\n  File \"/Library/Frameworks/Python.framework/Versions/3.6/lib/python3.6/site-packages/_pytest/outcomes.py\", line 116, in fail\n    raise Failed(msg=msg, pytrace=pytrace)\n"}, "start": 1559919276302, "stop": 1559919276310}], "start": 1559919276295, "stop": 1559919276310}